<?xml version="1.0" ?>
<robot name="egu60" xmlns:xacro="http://ros.org/wiki/xacro">
	<link name="base_link">
		<inertial>
			<mass value="2.9"/>
			<origin xyz="0       0     0"/>
			<inertia ixx="0.0048282" ixy="4.1298e-06" ixz="6.9879e-06" iyy="0.0059519"
				iyz="4.252e-06"
				izz="0.0061263"/>
		</inertial>
		<collision>
			<origin rpy="0 0 1.571" xyz="0 0 0" />
			<geometry>
				<mesh filename="package://dsr_description2/meshes/m1013_gripper/gripper_collision_1.dae" scale="1 1 1" />
			</geometry>
		</collision>
		<visual>
			<origin rpy="0 0 0" xyz="0 0 0" />
			<geometry>
				<mesh filename="package://dsr_description2/meshes/m1013_gripper/gripper_wo_fingers.dae" scale="1 1 1" />
			</geometry>
		</visual>
	</link>

	<joint name="left_finger_joint" type="prismatic">
		<parent link="base_link"/>
		<child link="left_finger"/>
		<axis xyz="0 0 1"/>
		<limit lower="0.0" upper="0.06" effort="100.0" velocity="0.2"/>
	</joint>

	<joint name="right_finger_joint" type="prismatic">
		<parent link="base_link"/>
		<child link="right_finger"/>
		<origin xyz="0 0 0" rpy="0 0 0"/>
		<axis xyz="0 0 -1"/>
		<limit lower="0.0" upper="0.06" effort="100.0" velocity="0.2"/>
		<mimic joint="left_finger_joint" multiplier="1.0" offset="0.0"/>
	</joint>

<!-- left finger -->
<link name="left_finger">
	<inertial>
		<mass value="0.1"/>
		<origin xyz="0 0 0"/>
		<inertia ixx="1e-5" ixy="0" ixz="0" iyy="1e-5" iyz="0" izz="1e-5"/>
	</inertial>
	<collision>
		<origin xyz="0 0 0" rpy="0 0 0"/>
		<geometry>
			<mesh filename="package://dsr_description2/meshes/m1013_gripper/finger_left.dae" scale="1 1 1"/>
		</geometry>
	</collision>
	<visual>
		<origin xyz="0 0 0" rpy="0 0 0"/>
		<geometry>
			<mesh filename="package://dsr_description2/meshes/m1013_gripper/finger_left.dae" scale="1 1 1"/>
		</geometry>
	</visual>
</link>

<!-- right finger -->
<link name="right_finger">
	<inertial>
		<mass value="0.1"/>
		<origin xyz="0 0 0"/>
		<inertia ixx="1e-5" ixy="0" ixz="0" iyy="1e-5" iyz="0" izz="1e-5"/>
	</inertial>
	<collision>
		<origin xyz="0 0 0" rpy="0 0 0"/>
		<geometry>
			<mesh filename="package://dsr_description2/meshes/m1013_gripper/finger_right.dae" scale="1 1 1"/>
		</geometry>
	</collision>
	<visual>
		<origin xyz="0 0 0" rpy="0 0 0"/>
		<geometry>
			<mesh filename="package://dsr_description2/meshes/m1013_gripper/finger_right.dae" scale="1 1 1"/>
		</geometry>
	</visual>
</link>

<joint name="left_finger_extension_joint" type="fixed">
	<parent link="left_finger" />
	<child link="left_finger_extension" />
	<origin rpy="0 0 0" xyz="0 0 0" />
	<dynamics friction="0" />
</joint>

<!-- left finger extension -->
<link name="left_finger_extension">
	<inertial>
		<mass value="0.1"/>
		<origin xyz="0 0 0"/>
		<inertia ixx="1e-5" ixy="0" ixz="0" iyy="1e-5" iyz="0" izz="1e-5"/>
	</inertial>
	<collision>
		<origin xyz="0 0 0" rpy="0 0 0"/>
		<geometry>
			<mesh filename="package://dsr_description2/meshes/m1013_gripper/finger_extension.dae" scale="1 1 1"/>
		</geometry>
	</collision>
	<visual>
		<origin xyz="0 0 0" rpy="0 0 0"/>
		<geometry>
			<mesh filename="package://dsr_description2/meshes/m1013_gripper/finger_extension.dae" scale="1 1 1"/>
		</geometry>
	</visual>
</link>


</robot>